Workbook

Sheet README
A2: Retail Sales & Inventory Dashboard
A4: Project Overview
A6: This workbook analyses 60 sales transactions across 4 regions (North, South, East, West)
A7: and 5 sales reps, using a master list of 15 products as the lookup reference.
A9: It answers two business questions:
A10: 1. Which product categories and regions drive the most revenue?
A11: 2. Which products are running low on stock and need reordering?
A13: Sheet Guide
A15: Product_Lookup | B15: Master list of 15 products — ProductID, Name, Category, UnitPrice, ReorderLevel, CurrentStock
A16: Sales_Data | B16: 60 raw transactions enriched with VLOOKUP formulas for Name, Category, Price, and an IF stock flag
A17: Analysis | B17: Labeled formula scratchpad — COUNTIF, COUNTIFS, SUMIF, SUMIFS, AVERAGEIF, XLOOKUP demo
A18: Pivot_Summary | B18: Category × Region revenue cross-tab built with SUMIFS; build the live PivotTable version here too
A19: Dashboard | B19: 4 KPI cards (Total Revenue, Orders, Avg Order Value, Products to Reorder) + Bar chart + Pie chart
A21: Key Formulas Used
A23: VLOOKUP | B23: Pulls ProductName, Category, UnitPrice from Product_Lookup into every Sales_Data row
A24: XLOOKUP | B24: Modern alternative to VLOOKUP — no column index needed; works leftward (Excel 2021/365 only)
A25: IF | B25: Flags each order row as 'Reorder Now' or 'OK' by comparing CurrentStock to ReorderLevel
A26: COUNTIF | B26: Counts orders matching one condition — e.g. all orders in the North region
A27: COUNTIFS | B27: Counts orders matching two+ conditions — e.g. North region AND Electronics category
A28: SUMIF | B28: Sums TotalSale for one condition — e.g. total revenue from Electronics
A29: SUMIFS | B29: Sums TotalSale for two+ conditions — e.g. North region AND Electronics revenue
A30: AVERAGEIF | B30: Average order value for a single sales rep
A31: COUNTA | B31: Total number of orders (counts non-empty cells in the OrderID column)
A32: SUM / AVERAGE | B32: Grand total revenue and average order value on the Dashboard KPI cards
A34: Data Specifications
A36: Date range | B36: January 2026 – March 2026
A37: Orders | B37: 60 transactions (rows 2–61 in Sales_Data)
A38: Products | B38: 15 SKUs across 4 categories: Electronics, Stationery, Furniture, Accessories
A39: Regions | B39: North | South | East | West
A40: Sales reps | B40: Asha | Rohan | Maria | Devon | Priya
A41: Price range | B41: $3.75 (Sticky Notes) – $299.00 (Standing Desk)
A43: Interview Skills Checklist
A45: ☐ VLOOKUP / XLOOKUP — enrich a flat transaction table from a reference table
A46: ☐ Nested IF + VLOOKUP — flag records based on a condition from another table
A47: ☐ COUNTIF / COUNTIFS — count rows matching one or multiple conditions
A48: ☐ SUMIF / SUMIFS — sum values matching one or multiple conditions
A49: ☐ AVERAGEIF — conditional average
A50: ☐ PivotTable — drag-and-drop Category × Region × TotalSale summary
A51: ☐ Charts — clustered bar (by category) and pie (by region) from PivotTable data
A52: ☐ AutoFilter — filter + cross-check against COUNTIFS to validate formulas
...

Sheet Product_Lookup 
A1: ProductID | B1: ProductName | C1: Category | D1: UnitPrice | E1: ReorderLevel | F1: CurrentStock
A2: P001 | B2: Wireless Mouse | C2: Electronics | D2: 25.99 | E2: 20 | F2: 15
A3: P002 | B3: USB-C Cable | C3: Electronics | D3: 12.5 | E3: 30 | F3: 45
A4: P003 | B4: Bluetooth Speaker | C4: Electronics | D4: 45 | E4: 15 | F4: 8
A5: P004 | B5: Laptop Stand | C5: Accessories | D5: 35 | E5: 10 | F5: 12
A6: P005 | B6: Mechanical Keyboard | C6: Electronics | D6: 89.99 | E6: 10 | F6: 5
A7: P006 | B7: Notebook Set | C7: Stationery | D7: 8.5 | E7: 50 | F7: 60
A8: P007 | B8: Gel Pens (Pack of 10) | C8: Stationery | D8: 6.25 | E8: 40 | F8: 35
A9: P008 | B9: Sticky Notes | C9: Stationery | D9: 3.75 | E9: 60 | F9: 70
A10: P009 | B10: Desk Organizer | C10: Furniture | D10: 22 | E10: 15 | F10: 18
A11: P010 | B11: Office Chair | C11: Furniture | D11: 145 | E11: 5 | F11: 3
A12: P011 | B12: Standing Desk | C12: Furniture | D12: 299 | E12: 4 | F12: 2
A13: P012 | B13: Webcam HD | C13: Electronics | D13: 55 | E13: 12 | F13: 9
... A16: P015 | B16: Monitor 24-inch | C16: Electronics | D16: 159.99 | E16: 8 | F16: 4

Sheet Sales_Data
A1: OrderID | B1: OrderDate | C1: ProductID | D1: Quantity | E1: Region | F1: SalesRep | G1: ProductName | H1: category | I1: UnitPrice | J1: TotalSales | K1: StockStatus
A2: O1042 | B2: 46055 | C2: P001 | D2: 1 | E2: North | F2: Rohan | G2: =VLOOKUP(C2,'Product_Lookup '!$A$2:$F$16,2,FALSE) -> Wireless Mouse | H2: =VLOOKUP(C2,'Product_Lookup '!$A$2:$F$16,3,FALSE) -> Electronics | I2: =VLOOKUP(C2,'Product_Lookup '!$A$2:$F$16,4,FALSE) -> 25.99 | J2: =I2*D2 -> 25.99 | K2: =IF(VLOOKUP(C2,'Product_Lookup '!$A$2:$F$16,6,FALSE)<VLOOKUP(C2,'Product_Lookup '!$A$2:$F$16,5,FALSE),"Reorder Now","OK") -> Reorder Now
A3: O1059 | B3: 46096 | C3: P001 | D3: 6 | E3: East | F3: Asha | G3: =VLOOKUP(C3,'Product_Lookup '!$A$2:$F$16,2,FALSE) -> Wireless Mouse | H3: =VLOOKUP(C3,'Product_Lookup '!$A$2:$F$16,3,FALSE) -> Electronics | I3: =VLOOKUP(C3,'Product_Lookup '!$A$2:$F$16,4,FALSE) -> 25.99 | J3: =I3*D3 -> 155.94 | K3: =IF(VLOOKUP(C3,'Product_Lookup '!$A$2:$F$16,6,FALSE)<VLOOKUP(C3,'Product_Lookup '!$A$2:$F$16,5,FALSE),"Reorder Now","OK") -> Reorder Now
A4: O1001 | B4: 46108 | C4: P002 | D4: 1 | E4: East | F4: Rohan | G4: =VLOOKUP(C4,'Product_Lookup '!$A$2:$F$16,2,FALSE) -> USB-C Cable | H4: =VLOOKUP(C4,'Product_Lookup '!$A$2:$F$16,3,FALSE) -> Electronics | I4: =VLOOKUP(C4,'Product_Lookup '!$A$2:$F$16,4,FALSE) -> 12.5 | J4: =I4*D4 -> 12.5 | K4: =IF(VLOOKUP(C4,'Product_Lookup '!$A$2:$F$16,6,FALSE)<VLOOKUP(C4,'Product_Lookup '!$A$2:$F$16,5,FALSE),"Reorder Now","OK") -> OK
A5: O1008 | B5: 46070 | C5: P002 | D5: 1 | E5: West | F5: Asha | G5: =VLOOKUP(C5,'Product_Lookup '!$A$2:$F$16,2,FALSE) -> USB-C Cable | H5: =VLOOKUP(C5,'Product_Lookup '!$A$2:$F$16,3,FALSE) -> Electronics | I5: =VLOOKUP(C5,'Product_Lookup '!$A$2:$F$16,4,FALSE) -> 12.5 | J5: =I5*D5 -> 12.5 | K5: =IF(VLOOKUP(C5,'Product_Lookup '!$A$2:$F$16,6,FALSE)<VLOOKUP(C5,'Product_Lookup '!$A$2:$F$16,5,FALSE),"Reorder Now","OK") -> OK
A6: O1013 | B6: 46064 | C6: P002 | D6: 2 | E6: North | F6: Devon | G6: =VLOOKUP(C6,'Product_Lookup '!$A$2:$F$16,2,FALSE) -> USB-C Cable | H6: =VLOOKUP(C6,'Product_Lookup '!$A$2:$F$16,3,FALSE) -> Electronics | I6: =VLOOKUP(C6,'Product_Lookup '!$A$2:$F$16,4,FALSE) -> 12.5 | J6: =I6*D6 -> 25 | K6: =IF(VLOOKUP(C6,'Product_Lookup '!$A$2:$F$16,6,FALSE)<VLOOKUP(C6,'Product_Lookup '!$A$2:$F$16,5,FALSE),"Reorder Now","OK") -> OK
A7: O1019 | B7: 46061 | C7: P002 | D7: 2 | E7: East | F7: Rohan | G7: =VLOOKUP(C7,'Product_Lookup '!$A$2:$F$16,2,FALSE) -> USB-C Cable | H7: =VLOOKUP(C7,'Product_Lookup '!$A$2:$F$16,3,FALSE) -> Electronics | I7: =VLOOKUP(C7,'Product_Lookup '!$A$2:$F$16,4,FALSE) -> 12.5 | J7: =I7*D7 -> 25 | K7: =IF(VLOOKUP(C7,'Product_Lookup '!$A$2:$F$16,6,FALSE)<VLOOKUP(C7,'Product_Lookup '!$A$2:$F$16,5,FALSE),"Reorder Now","OK") -> OK
A8: O1035 | B8: 46037 | C8: P002 | D8: 6 | E8: West | F8: Asha | G8: =VLOOKUP(C8,'Product_Lookup '!$A$2:$F$16,2,FALSE) -> USB-C Cable | H8: =VLOOKUP(C8,'Product_Lookup '!$A$2:$F$16,3,FALSE) -> Electronics | I8: =VLOOKUP(C8,'Product_Lookup '!$A$2:$F$16,4,FALSE) -> 12.5 | J8: =I8*D8 -> 75 | K8: =IF(VLOOKUP(C8,'Product_Lookup '!$A$2:$F$16,6,FALSE)<VLOOKUP(C8,'Product_Lookup '!$A$2:$F$16,5,FALSE),"Reorder Now","OK") -> OK
A9: O1002 | B9: 46055 | C9: P003 | D9: 6 | E9: North | F9: Priya | G9: =VLOOKUP(C9,'Product_Lookup '!$A$2:$F$16,2,FALSE) -> Bluetooth Speaker | H9: =VLOOKUP(C9,'Product_Lookup '!$A$2:$F$16,3,FALSE) -> Electronics | I9: =VLOOKUP(C9,'Product_Lookup '!$A$2:$F$16,4,FALSE) -> 45 | J9: =I9*D9 -> 270 | K9: =IF(VLOOKUP(C9,'Product_Lookup '!$A$2:$F$16,6,FALSE)<VLOOKUP(C9,'Product_Lookup '!$A$2:$F$16,5,FALSE),"Reorder Now","OK") -> Reorder Now
A10: O1021 | B10: 46060 | C10: P003 | D10: 2 | E10: East | F10: Priya | G10: =VLOOKUP(C10,'Product_Lookup '!$A$2:$F$16,2,FALSE) -> Bluetooth Speaker | H10: =VLOOKUP(C10,'Product_Lookup '!$A$2:$F$16,3,FALSE) -> Electronics | I10: =VLOOKUP(C10,'Product_Lookup '!$A$2:$F$16,4,FALSE) -> 45 | J10: =I10*D10 -> 90 | K10: =IF(VLOOKUP(C10,'Product_Lookup '!$A$2:$F$16,6,FALSE)<VLOOKUP(C10,'Product_Lookup '!$A$2:$F$16,5,FALSE),"Reorder Now","OK") -> Reorder Now
A11: O1023 | B11: 46055 | C11: P003 | D11: 5 | E11: West | F11: Asha | G11: =VLOOKUP(C11,'Product_Lookup '!$A$2:$F$16,2,FALSE) -> Bluetooth Speaker | H11: =VLOOKUP(C11,'Product_Lookup '!$A$2:$F$16,3,FALSE) -> Electronics | I11: =VLOOKUP(C11,'Product_Lookup '!$A$2:$F$16,4,FALSE) -> 45 | J11: =I11*D11 -> 225 | K11: =IF(VLOOKUP(C11,'Product_Lookup '!$A$2:$F$16,6,FALSE)<VLOOKUP(C11,'Product_Lookup '!$A$2:$F$16,5,FALSE),"Reorder Now","OK") -> Reorder Now
A12: O1037 | B12: 46097 | C12: P003 | D12: 3 | E12: West | F12: Rohan | G12: =VLOOKUP(C12,'Product_Lookup '!$A$2:$F$16,2,FALSE) -> Bluetooth Speaker | H12: =VLOOKUP(C12,'Product_Lookup '!$A$2:$F$16,3,FALSE) -> Electronics | I12: =VLOOKUP(C12,'Product_Lookup '!$A$2:$F$16,4,FALSE) -> 45 | J12: =I12*D12 -> 135 | K12: =IF(VLOOKUP(C12,'Product_Lookup '!$A$2:$F$16,6,FALSE)<VLOOKUP(C12,'Product_Lookup '!$A$2:$F$16,5,FALSE),"Reorder Now","OK") -> Reorder Now
A13: O1045 | B13: 46096 | C13: P003 | D13: 6 | E13: West | F13: Rohan | G13: =VLOOKUP(C13,'Product_Lookup '!$A$2:$F$16,2,FALSE) -> Bluetooth Speaker | H13: =VLOOKUP(C13,'Product_Lookup '!$A$2:$F$16,3,FALSE) -> Electronics | I13: =VLOOKUP(C13,'Product_Lookup '!$A$2:$F$16,4,FALSE) -> 45 | J13: =I13*D13 -> 270 | K13: =IF(VLOOKUP(C13,'Product_Lookup '!$A$2:$F$16,6,FALSE)<VLOOKUP(C13,'Product_Lookup '!$A$2:$F$16,5,FALSE),"Reorder Now","OK") -> Reorder Now
... A61: O1055 | B61: 46078 | C61: P015 | D61: 1 | E61: South | F61: Devon | G61: =VLOOKUP(C61,'Product_Lookup '!$A$2:$F$16,2,FALSE) -> Monitor 24-inch | H61: =VLOOKUP(C61,'Product_Lookup '!$A$2:$F$16,3,FALSE) -> Electronics | I61: =VLOOKUP(C61,'Product_Lookup '!$A$2:$F$16,4,FALSE) -> 159.99 | J61: =I61*D61 -> 159.99 | K61: =IF(VLOOKUP(C61,'Product_Lookup '!$A$2:$F$16,6,FALSE)<VLOOKUP(C61,'Product_Lookup '!$A$2:$F$16,5,FALSE),"Reorder Now","OK") -> Reorder Now

Sheet Analysis
A1: Metric | B1: Result
A2: Total Orders | B2: =COUNTA(Sales_Data!A2:A65) -> 60
A3: Orders in North region | B3: =COUNTIF(Sales_Data!E2:E65,"north") -> 15
A4: Orders: North AND Electronics | B4: =COUNTIFS(Sales_Data!E2:E65,"north",Sales_Data!H2:H65,"Electronics") -> 5
A5: Revenue from Electronics | B5: =SUMIF(Sales_Data!H2:H65,"Electronics",Sales_Data!J2:J65) -> 4011.78
A6: Revenue: North AND Electronics | B6: =SUMIFS(Sales_Data!J2:J65,Sales_Data!E2:E65,"north",Sales_Data!H2:H65,"Electronics") -> 555.97
A7: Avg order value — Priya | B7: =AVERAGEIF(Sales_Data!F2:F65,"Priya",Sales_Data!J2:J65) -> 303.815
A8: Orders flagged for reorder | B8: =COUNTIF(Sales_Data!K2:K65,"Reorder Now") -> 31

Sheet Pivot_Summary
A1: SalesRep | B1: (All)
A3: Sum of TotalSales | B3: Column Labels
A4: Row Labels | B4: East | C4: North | D4: South | E4: West | F4: Grand Total
A5: Accessories | B5: 258.44 | C5: 101.98 | D5: 269.38 | E5: 175 | F5: 804.8
A6: Electronics | B6: 983.37 | C6: 555.97 | D6: 159.99 | E6: 2312.45 | F6: 4011.78
A7: Furniture | B7: 2990 | C7: 2875 | D7: 1288 | E7: 167 | F7: 7320
A8: Stationery | B8: 95.75 | C8: 45 | D8: 56.5 | E8: 71.25 | F8: 268.5
A9: Grand Total | B9: 4327.56 | C9: 3577.95 | D9: 1773.87 | E9: 2725.7 | F9: 12405.08

Sheet Dashboard
B2: Sales Dashboard
B4: Total Revenue | C4: Total orders | D4: Avg Order Value | E4: Products to Reorder
B5: =SUM(Sales_Data!J2:J61) -> 12405.08 | C5: =COUNTA(Sales_Data!A2:A61) -> 60 | D5: =AVERAGE(Sales_Data!J2:J61) -> 206.75133 | E5: =COUNTIF(Sales_Data!K2:K61,"Reorder Now") -> 31
